Workbook

Sheet Room Selection
A2: - Select Action -
B3: Room Affected | C3: QTY
A4: FALSE | B4: Kitchen | C4: 1
A5: FALSE | B5: Dining Room | C5: 1
A6: FALSE | B6: Pantry | C6: 1
A7: FALSE | B7: Master Bathroom | C7: 1
A8: FALSE | B8: Bathroom | C8: 1
A9: FALSE | B9: Toilet Room | C9: 1
A10: FALSE | B10: Master Bedroom | C10: 1
A11: FALSE | B11: Bedroom | C11: 1
A12: FALSE | B12: Living Room | C12: 1
A13: FALSE | B13: Family Room | C13: 1
A14: FALSE | B14: Laundry Room | C14: 1
A15: FALSE | B15: Hallway | C15: 1
... A23: FALSE | B23: Wet Bar | C23: 1

Sheet Daily Time  Readings Log
J1: Daily Time / Readings Log
J2: Entrusted
A3: Customer Name:
A5: Date | B5: # Techs | C5: Foreman | D5: Tech(s) Names | E5: Specialized | F5: Outside RH (%) Temp ( °) | H5: Unaffected RH (%) Temp ( °) | J5: Arrival Time | K5: Ending Time | L5: Travel (Mins) | M5: Demo Time (Mins) | N5: During Hrs | O5: After Hrs | S5: Tech During Hrs | T5: Tech After Hrs | U5: Total Tech Hrs | V5: Total Daily During Hrs | W5: Total Daily After Hrs | X5: Total Daily Hrs | Y5: Foreman During Hrs | Z5: Foreman After Hrs | AA5: None | AB5: Testing | AC5: Microbial Present | AD5: Biohazardous | AE5: Lead Abatement | AF5: Travel Time (Hrs) | AG5: T | AH5: T | AI5: Testing Final | AJ5: M.P. | AK5: M.P. | AL5: M.P. | AM5: M.P. Final | AN5: BIO | AO5: BIO | AP5: BIO Final | AQ5: L.A. | AR5: L.A. | AS5: L.A. Final
N6: =V6 -> 0 | O6: =W6 -> 0 | P6: =sum(N6:O6) -> 0 | S6: =sum(Formulas!AI3*'Daily Time Readings Log'!B6) -> 0 | T6: =sum(Formulas!AJ3*'Daily Time Readings Log'!B6) -> 0 | U6: =sum(N6+O6) -> 0 | V6: =sum(S6+Y6) -> 0 | W6: =sum(T6+Z6) -> 0 | X6: =sum(V6+W6) -> 0 | Y6: =sum(Formulas!AI3*'Daily Time Readings Log'!C6) -> 0 | Z6: =sum(Formulas!AJ3*'Daily Time Readings Log'!C6) -> 0 | AA6: =if((E6="None"),0,0) -> 0 | AB6: =if((AND(N6>1,E6="T")),1,0) -> 0 | AC6: =if((AND(N6>1,E6="M.P.")),1,0) -> 0 | AD6: =if((AND(E6="BIO",AF6 >= S6)),0,S6-AF6) -> 0 | AE6: =if((AND(E6="L.A.",AF6>=S6)),0,S6-AF6) -> 0 | AF6: =(L6/60) -> 0 | AG6: =if((E6="T"),Formulas!AG3,0) -> 0 | AH6: =if((AG6<1),AG6,1) -> 0 | AI6: =if((B6=0),0,AH6) -> 0 | AJ6: =if((E6="M.P."),Formulas!AG3,0) -> 0 | AK6: =if((AJ6<1),AJ6,1) -> 0 | AL6: =if((B6=0),0,AK6) -> 0 | AM6: =sum(AL6*B6) -> 0 | AN6: =if((E6="BIO"),S6,0) -> 0 | AO6: =sum(AN6*1) -> 0 | AP6: =if((AO6>0),(AO6-Formulas!AM3),0) -> 0 | AQ6: =if((E6="L.A."),S6,0) -> 0 | AR6: =sum(AQ6*1) -> 0 | AS6: =if((AR6>0),(AR6-Formulas!AM3),0) -> 0
N7: =V7 -> 0 | O7: =W7 -> 0 | P7: =sum(N7:O7) -> 0 | S7: =sum(Formulas!AI4*'Daily Time Readings Log'!B7) -> 0 | T7: =sum(Formulas!AJ4*'Daily Time Readings Log'!B7) -> 0 | U7: =sum(N7+O7) -> 0 | V7: =sum(S7+Y7) -> 0 | W7: =sum(T7+Z7) -> 0 | X7: =sum(V7+W7) -> 0 | Y7: =sum(Formulas!AI4*'Daily Time Readings Log'!C7) -> 0 | Z7: =sum(Formulas!AJ4*'Daily Time Readings Log'!C7) -> 0 | AA7: =if((E7="None"),0,0) -> 0 | AB7: =if((AND(N7>1,E7="T")),1,0) -> 0 | AC7: =if((AND(N7>1,E7="M.P.")),1,0) -> 0 | AD7: =if((E7="BIO"),S7-AF7,0) -> 0 | AE7: =if((E7="L.A."),S7-AF7,0) -> 0 | AF7: =(L7/60) -> 0 | AG7: =if((E7="T"),Formulas!AG4,0) -> 0 | AH7: =if((AG7<1),AG7,1) -> 0 | AI7: =if((B7=0),0,AH7) -> 0 | AJ7: =if((E7="M.P."),Formulas!AG4,0) -> 0 | AK7: =if((AJ7<1),AJ7,1) -> 0 | AL7: =if((B7=0),0,AK7) -> 0 | AM7: =sum(AL7*B7) -> 0 | AN7: =if((E7="BIO"),N7,0) -> 0 | AO7: =sum(AN7*1) -> 0 | AP7: =if((AO7>0),(AO7-Formulas!AM4),0) -> 0 | AQ7: =if((E7="L.A."),N7,0) -> 0 | AR7: =sum(AQ7*1) -> 0 | AS7: =if((AR7>0),(AR7-Formulas!AM4),0) -> 0
N8: =V8 -> 0 | O8: =W8 -> 0 | P8: =sum(N8:O8) -> 0 | S8: =sum(Formulas!AI5*'Daily Time Readings Log'!B8) -> 0 | T8: =sum(Formulas!AJ5*'Daily Time Readings Log'!B8) -> 0 | U8: =sum(N8+O8) -> 0 | V8: =sum(S8+Y8) -> 0 | W8: =sum(T8+Z8) -> 0 | X8: =sum(V8+W8) -> 0 | Y8: =sum(Formulas!AI5*'Daily Time Readings Log'!C8) -> 0 | Z8: =sum(Formulas!AJ5*'Daily Time Readings Log'!C8) -> 0 | AA8: =if((E8="None"),0,0) -> 0 | AB8: =if((AND(N8>1,E8="T")),1,0) -> 0 | AC8: =if((AND(N8>1,E8="M.P.")),1,0) -> 0 | AD8: =if((E8="BIO"),S8-AF8,0) -> 0 | AE8: =if((E8="L.A."),S8-AF8,0) -> 0 | AF8: =(L8/60) -> 0 | AG8: =if((E8="T"),Formulas!AG5,0) -> 0 | AH8: =if((AG8<1),AG8,1) -> 0 | AI8: =if((B8=0),0,AH8) -> 0 | AJ8: =if((E8="M.P."),Formulas!AG5,0) -> 0 | AK8: =if((AJ8<1),AJ8,1) -> 0 | AL8: =if((B8=0),0,AK8) -> 0 | AM8: =sum(AL8*B8) -> 0 | AN8: =if((E8="BIO"),N8,0) -> 0 | AO8: =sum(AN8*1) -> 0 | AP8: =if((AO8>0),(AO8-Formulas!AM5),0) -> 0 | AQ8: =if((E8="L.A."),N8,0) -> 0 | AR8: =sum(AQ8*1) -> 0 | AS8: =if((AR8>0),(AR8-Formulas!AM5),0) -> 0
N9: =V9 -> 0 | O9: =W9 -> 0 | P9: =sum(N9:O9) -> 0 | S9: =sum(Formulas!AI6*'Daily Time Readings Log'!B9) -> 0 | T9: =sum(Formulas!AJ6*'Daily Time Readings Log'!B9) -> 0 | U9: =sum(N9+O9) -> 0 | V9: =sum(S9+Y9) -> 0 | W9: =sum(T9+Z9) -> 0 | X9: =sum(V9+W9) -> 0 | Y9: =sum(Formulas!AI6*'Daily Time Readings Log'!C9) -> 0 | Z9: =sum(Formulas!AJ6*'Daily Time Readings Log'!C9) -> 0 | AA9: =if((E9="None"),0,0) -> 0 | AB9: =if((AND(N9>1,E9="T")),1,0) -> 0 | AC9: =if((AND(N9>1,E9="M.P.")),1,0) -> 0 | AD9: =if((E9="BIO"),S9-AF9,0) -> 0 | AE9: =if((E9="L.A."),S9-AF9,0) -> 0 | AF9: =(L9/60) -> 0 | AG9: =if((E9="T"),Formulas!AG6,0) -> 0 | AH9: =if((AG9<1),AG9,1) -> 0 | AI9: =if((B9=0),0,AH9) -> 0 | AJ9: =if((E9="M.P."),Formulas!AG6,0) -> 0 | AK9: =if((AJ9<1),AJ9,1) -> 0 | AL9: =if((B9=0),0,AK9) -> 0 | AM9: =sum(AL9*B9) -> 0 | AN9: =if((E9="BIO"),N9,0) -> 0 | AO9: =sum(AN9*1) -> 0 | AP9: =if((AO9>0),(AO9-Formulas!AM6),0) -> 0 | AQ9: =if((E9="L.A."),N9,0) -> 0 | AR9: =sum(AQ9*1) -> 0 | AS9: =if((AR9>0),(AR9-Formulas!AM6),0) -> 0
N10: =V10 -> 0 | O10: =W10 -> 0 | P10: =sum(N10:O10) -> 0 | S10: =sum(Formulas!AI7*'Daily Time Readings Log'!B10) -> 0 | T10: =sum(Formulas!AJ7*'Daily Time Readings Log'!B10) -> 0 | U10: =sum(N10+O10) -> 0 | V10: =sum(S10+Y10) -> 0 | W10: =sum(T10+Z10) -> 0 | X10: =sum(V10+W10) -> 0 | Y10: =sum(Formulas!AI7*'Daily Time Readings Log'!C10) -> 0 | Z10: =sum(Formulas!AJ7*'Daily Time Readings Log'!C10) -> 0 | AA10: =if((E10="None"),0,0) -> 0 | AB10: =if((AND(N10>1,E10="T")),1,0) -> 0 | AC10: =if((AND(N10>1,E10="M.P.")),1,0) -> 0 | AD10: =if((E10="BIO"),S10-AF10,0) -> 0 | AE10: =if((E10="L.A."),S10-AF10,0) -> 0 | AF10: =(L10/60) -> 0 | AG10: =if((E10="T"),Formulas!AG7,0) -> 0 | AH10: =if((AG10<1),AG10,1) -> 0 | AI10: =if((B10=0),0,AH10) -> 0 | AJ10: =if((E10="M.P."),Formulas!AG7,0) -> 0 | AK10: =if((AJ10<1),AJ10,1) -> 0 | AL10: =if((B10=0),0,AK10) -> 0 | AM10: =sum(AL10*B10) -> 0 | AN10: =if((E10="BIO"),N10,0) -> 0 | AO10: =sum(AN10*1) -> 0 | AP10: =if((AO10>0),(AO10-Formulas!AM7),0) -> 0 | AQ10: =if((E10="L.A."),N10,0) -> 0 | AR10: =sum(AQ10*1) -> 0 | AS10: =if((AR10>0),(AR10-Formulas!AM7),0) -> 0
N11: =V11 -> 0 | O11: =W11 -> 0 | P11: =sum(N11:O11) -> 0 | S11: =sum(Formulas!AI8*'Daily Time Readings Log'!B11) -> 0 | T11: =sum(Formulas!AJ8*'Daily Time Readings Log'!B11) -> 0 | U11: =sum(N11+O11) -> 0 | V11: =sum(S11+Y11) -> 0 | W11: =sum(T11+Z11) -> 0 | X11: =sum(V11+W11) -> 0 | Y11: =sum(Formulas!AI8*'Daily Time Readings Log'!C11) -> 0 | Z11: =sum(Formulas!AJ8*'Daily Time Readings Log'!C11) -> 0 | AA11: =if((E11="None"),0,0) -> 0 | AB11: =if((AND(N11>1,E11="T")),1,0) -> 0 | AC11: =if((AND(N11>1,E11="M.P.")),1,0) -> 0 | AD11: =if((E11="BIO"),S11-AF11,0) -> 0 | AE11: =if((E11="L.A."),S11-AF11,0) -> 0 | AF11: =(L11/60) -> 0 | AG11: =if((E11="T"),Formulas!AG8,0) -> 0 | AH11: =if((AG11<1),AG11,1) -> 0 | AI11: =if((B11=0),0,AH11) -> 0 | AJ11: =if((E11="M.P."),Formulas!AG8,0) -> 0 | AK11: =if((AJ11<1),AJ11,1) -> 0 | AL11: =if((B11=0),0,AK11) -> 0 | AM11: =sum(AL11*B11) -> 0 | AN11: =if((E11="BIO"),N11,0) -> 0 | AO11: =sum(AN11*1) -> 0 | AP11: =if((AO11>0),(AO11-Formulas!AM8),0) -> 0 | AQ11: =if((E11="L.A."),N11,0) -> 0 | AR11: =sum(AQ11*1) -> 0 | AS11: =if((AR11>0),(AR11-Formulas!AM8),0) -> 0
N12: =V12 -> 0 | O12: =W12 -> 0 | P12: =sum(N12:O12) -> 0 | S12: =sum(Formulas!AI9*'Daily Time Readings Log'!B12) -> 0 | T12: =sum(Formulas!AJ9*'Daily Time Readings Log'!B12) -> 0 | U12: =sum(N12+O12) -> 0 | V12: =sum(S12+Y12) -> 0 | W12: =sum(T12+Z12) -> 0 | X12: =sum(V12+W12) -> 0 | Y12: =sum(Formulas!AI9*'Daily Time Readings Log'!C12) -> 0 | Z12: =sum(Formulas!AJ9*'Daily Time Readings Log'!C12) -> 0 | AA12: =if((E12="None"),0,0) -> 0 | AB12: =if((AND(N12>1,E12="T")),1,0) -> 0 | AC12: =if((AND(N12>1,E12="M.P.")),1,0) -> 0 | AD12: =if((E12="BIO"),S12-AF12,0) -> 0 | AE12: =if((E12="L.A."),S12-AF12,0) -> 0 | AF12: =(L12/60) -> 0 | AG12: =if((E12="T"),Formulas!AG9,0) -> 0 | AH12: =if((AG12<1),AG12,1) -> 0 | AI12: =if((B12=0),0,AH12) -> 0 | AJ12: =if((E12="M.P."),Formulas!AG9,0) -> 0 | AK12: =if((AJ12<1),AJ12,1) -> 0 | AL12: =if((B12=0),0,AK12) -> 0 | AM12: =sum(AL12*B12) -> 0 | AN12: =if((E12="BIO"),N12,0) -> 0 | AO12: =sum(AN12*1) -> 0 | AP12: =if((AO12>0),(AO12-Formulas!AM9),0) -> 0 | AQ12: =if((E12="L.A."),N12,0) -> 0 | AR12: =sum(AQ12*1) -> 0 | AS12: =if((AR12>0),(AR12-Formulas!AM9),0) -> 0
N13: =V13 -> 0 | O13: =W13 -> 0 | P13: =sum(N13:O13) -> 0 | S13: =sum(Formulas!AI10*'Daily Time Readings Log'!B13) -> 0 | T13: =sum(Formulas!AJ10*'Daily Time Readings Log'!B13) -> 0 | U13: =sum(N13+O13) -> 0 | V13: =sum(S13+Y13) -> 0 | W13: =sum(T13+Z13) -> 0 | X13: =sum(V13+W13) -> 0 | Y13: =sum(Formulas!AI10*'Daily Time Readings Log'!C13) -> 0 | Z13: =sum(Formulas!AJ10*'Daily Time Readings Log'!C13) -> 0 | AA13: =if((E13="None"),0,0) -> 0 | AB13: =if((AND(N13>1,E13="T")),1,0) -> 0 | AC13: =if((AND(N13>1,E13="M.P.")),1,0) -> 0 | AD13: =if((E13="BIO"),S13-AF13,0) -> 0 | AE13: =if((E13="L.A."),S13-AF13,0) -> 0 | AF13: =(L13/60) -> 0 | AG13: =if((E13="T"),Formulas!AG10,0) -> 0 | AH13: =if((AG13<1),AG13,1) -> 0 | AI13: =if((B13=0),0,AH13) -> 0 | AJ13: =if((E13="M.P."),Formulas!AG10,0) -> 0 | AK13: =if((AJ13<1),AJ13,1) -> 0 | AL13: =if((B13=0),0,AK13) -> 0 | AM13: =sum(AL13*B13) -> 0 | AN13: =if((E13="BIO"),N13,0) -> 0 | AO13: =sum(AN13*1) -> 0 | AP13: =if((AO13>0),(AO13-Formulas!AM10),0) -> 0 | AQ13: =if((E13="L.A."),N13,0) -> 0 | AR13: =sum(AQ13*1) -> 0 | AS13: =if((AR13>0),(AR13-Formulas!AM10),0) -> 0
N14: =V14 -> 0 | O14: =W14 -> 0 | P14: =sum(N14:O14) -> 0 | S14: =sum(Formulas!AI11*'Daily Time Readings Log'!B14) -> 0 | T14: =sum(Formulas!AJ11*'Daily Time Readings Log'!B14) -> 0 | U14: =sum(N14+O14) -> 0 | V14: =sum(S14+Y14) -> 0 | W14: =sum(T14+Z14) -> 0 | X14: =sum(V14+W14) -> 0 | Y14: =sum(Formulas!AI11*'Daily Time Readings Log'!C14) -> 0 | Z14: =sum(Formulas!AJ11*'Daily Time Readings Log'!C14) -> 0 | AA14: =if((E14="None"),0,0) -> 0 | AB14: =if((AND(N14>1,E14="T")),1,0) -> 0 | AC14: =if((AND(N14>1,E14="M.P.")),1,0) -> 0 | AD14: =if((E14="BIO"),S14-AF14,0) -> 0 | AE14: =if((E14="L.A."),S14-AF14,0) -> 0 | AF14: =(L14/60) -> 0 | AG14: =if((E14="T"),Formulas!AG11,0) -> 0 | AH14: =if((AG14<1),AG14,1) -> 0 | AI14: =if((B14=0),0,AH14) -> 0 | AJ14: =if((E14="M.P."),Formulas!AG11,0) -> 0 | AK14: =if((AJ14<1),AJ14,1) -> 0 | AL14: =if((B14=0),0,AK14) -> 0 | AM14: =sum(AL14*B14) -> 0 | AN14: =if((E14="BIO"),N14,0) -> 0 | AO14: =sum(AN14*1) -> 0 | AP14: =if((AO14>0),(AO14-Formulas!AM11),0) -> 0 | AQ14: =if((E14="L.A."),N14,0) -> 0 | AR14: =sum(AQ14*1) -> 0 | AS14: =if((AR14>0),(AR14-Formulas!AM11),0) -> 0
N15: =V15 -> 0 | O15: =W15 -> 0 | P15: =sum(N15:O15) -> 0 | S15: =sum(Formulas!AI12*'Daily Time Readings Log'!B15) -> 0 | T15: =sum(Formulas!AJ12*'Daily Time Readings Log'!B15) -> 0 | U15: =sum(N15+O15) -> 0 | V15: =sum(S15+Y15) -> 0 | W15: =sum(T15+Z15) -> 0 | X15: =sum(V15+W15) -> 0 | Y15: =sum(Formulas!AI12*'Daily Time Readings Log'!C15) -> 0 | Z15: =sum(Formulas!AJ12*'Daily Time Readings Log'!C15) -> 0 | AA15: =if((E15="None"),0,0) -> 0 | AB15: =if((AND(N15>1,E15="T")),1,0) -> 0 | AC15: =if((AND(N15>1,E15="M.P.")),1,0) -> 0 | AD15: =if((E15="BIO"),S15-AF15,0) -> 0 | AE15: =if((E15="L.A."),S15-AF15,0) -> 0 | AF15: =(L15/60) -> 0 | AG15: =if((E15="T"),Formulas!AG12,0) -> 0 | AH15: =if((AG15<1),AG15,1) -> 0 | AI15: =if((B15=0),0,AH15) -> 0 | AJ15: =if((E15="M.P."),Formulas!AG12,0) -> 0 | AK15: =if((AJ15<1),AJ15,1) -> 0 | AL15: =if((B15=0),0,AK15) -> 0 | AM15: =sum(AL15*B15) -> 0 | AN15: =if((E15="BIO"),N15,0) -> 0 | AO15: =sum(AN15*1) -> 0 | AP15: =if((AO15>0),(AO15-Formulas!AM12),0) -> 0 | AQ15: =if((E15="L.A."),N15,0) -> 0 | AR15: =sum(AQ15*1) -> 0 | AS15: =if((AR15>0),(AR15-Formulas!AM12),0) -> 0
N16: =V16 -> 0 | O16: =W16 -> 0 | P16: =sum(N16:O16) -> 0 | S16: =sum(Formulas!AI13*'Daily Time Readings Log'!B16) -> 0 | T16: =sum(Formulas!AJ13*'Daily Time Readings Log'!B16) -> 0 | U16: =sum(N16+O16) -> 0 | V16: =sum(S16+Y16) -> 0 | W16: =sum(T16+Z16) -> 0 | X16: =sum(V16+W16) -> 0 | Y16: =sum(Formulas!AI13*'Daily Time Readings Log'!C16) -> 0 | Z16: =sum(Formulas!AJ13*'Daily Time Readings Log'!C16) -> 0 | AA16: =if((E16="None"),0,0) -> 0 | AB16: =if((AND(N16>1,E16="T")),1,0) -> 0 | AC16: =if((AND(N16>1,E16="M.P.")),1,0) -> 0 | AD16: =if((E16="BIO"),S16-AF16,0) -> 0 | AE16: =if((E16="L.A."),S16-AF16,0) -> 0 | AF16: =(L16/60) -> 0 | AG16: =if((E16="T"),Formulas!AG13,0) -> 0 | AH16: =if((AG16<1),AG16,1) -> 0 | AI16: =if((B16=0),0,AH16) -> 0 | AJ16: =if((E16="M.P."),Formulas!AG13,0) -> 0 | AK16: =if((AJ16<1),AJ16,1) -> 0 | AL16: =if((B16=0),0,AK16) -> 0 | AM16: =sum(AL16*B16) -> 0 | AN16: =if((E16="BIO"),N16,0) -> 0 | AO16: =sum(AN16*1) -> 0 | AP16: =if((AO16>0),(AO16-Formulas!AM13),0) -> 0 | AQ16: =if((E16="L.A."),N16,0) -> 0 | AR16: =sum(AQ16*1) -> 0 | AS16: =if((AR16>0),(AR16-Formulas!AM13),0) -> 0
N17: =V17 -> 0 | O17: =W17 -> 0 | P17: =sum(N17:O17) -> 0 | S17: =sum(Formulas!AI14*'Daily Time Readings Log'!B17) -> 0 | T17: =sum(Formulas!AJ14*'Daily Time Readings Log'!B17) -> 0 | U17: =sum(N17+O17) -> 0 | V17: =sum(S17+Y17) -> 0 | W17: =sum(T17+Z17) -> 0 | X17: =sum(V17+W17) -> 0 | Y17: =sum(Formulas!AI14*'Daily Time Readings Log'!C17) -> 0 | Z17: =sum(Formulas!AJ14*'Daily Time Readings Log'!C17) -> 0 | AA17: =if((E17="None"),0,0) -> 0 | AB17: =if((AND(N17>1,E17="T")),1,0) -> 0 | AC17: =if((AND(N17>1,E17="M.P.")),1,0) -> 0 | AD17: =if((E17="BIO"),S17-AF17,0) -> 0 | AE17: =if((E17="L.A."),S17-AF17,0) -> 0 | AF17: =(L17/60) -> 0 | AG17: =if((E17="T"),Formulas!AG14,0) -> 0 | AH17: =if((AG17<1),AG17,1) -> 0 | AI17: =if((B17=0),0,AH17) -> 0 | AJ17: =if((E17="M.P."),Formulas!AG14,0) -> 0 | AK17: =if((AJ17<1),AJ17,1) -> 0 | AL17: =if((B17=0),0,AK17) -> 0 | AM17: =sum(AL17*B17) -> 0 | AN17: =if((E17="BIO"),N17,0) -> 0 | AO17: =sum(AN17*1) -> 0 | AP17: =if((AO17>0),(AO17-Formulas!AM14),0) -> 0 | AQ17: =if((E17="L.A."),N17,0) -> 0 | AR17: =sum(AQ17*1) -> 0 | AS17: =if((AR17>0),(AR17-Formulas!AM14),0) -> 0
N18: =V18 -> 0 | O18: =W18 -> 0 | P18: =sum(N18:O18) -> 0 | S18: =sum(Formulas!AI15*'Daily Time Readings Log'!B18) -> 0 | T18: =sum(Formulas!AJ15*'Daily Time Readings Log'!B18) -> 0 | U18: =sum(N18+O18) -> 0 | V18: =sum(S18+Y18) -> 0 | W18: =sum(T18+Z18) -> 0 | X18: =sum(V18+W18) -> 0 | Y18: =sum(Formulas!AI15*'Daily Time Readings Log'!C18) -> 0 | Z18: =sum(Formulas!AJ15*'Daily Time Readings Log'!C18) -> 0 | AA18: =if((E18="None"),0,0) -> 0 | AB18: =if((AND(N18>1,E18="T")),1,0) -> 0 | AC18: =if((AND(N18>1,E18="M.P.")),1,0) -> 0 | AD18: =if((E18="BIO"),S18-AF18,0) -> 0 | AE18: =if((E18="L.A."),S18-AF18,0) -> 0 | AF18: =(L18/60) -> 0 | AG18: =if((E18="T"),Formulas!AG15,0) -> 0 | AH18: =if((AG18<1),AG18,1) -> 0 | AI18: =if((B18=0),0,AH18) -> 0 | AJ18: =if((E18="M.P."),Formulas!AG15,0) -> 0 | AK18: =if((AJ18<1),AJ18,1) -> 0 | AL18: =if((B18=0),0,AK18) -> 0 | AM18: =sum(AL18*B18) -> 0 | AN18: =if((E18="BIO"),N18,0) -> 0 | AO18: =sum(AN18*1) -> 0 | AP18: =if((AO18>0),(AO18-Formulas!AM15),0) -> 0 | AQ18: =if((E18="L.A."),N18,0) -> 0 | AR18: =sum(AQ18*1) -> 0 | AS18: =if((AR18>0),(AR18-Formulas!AM15),0) -> 0
... N40: =V40 -> 0 | O40: =W40 -> 0 | P40: =sum(N40:O40) -> 0 | S40: =sum(Formulas!AI37*'Daily Time Readings Log'!B40) -> 0 | T40: =sum(Formulas!AJ37*'Daily Time Readings Log'!B40) -> 0 | U40: =sum(N40+O40) -> 0 | V40: =sum(S40+Y40) -> 0 | W40: =sum(T40+Z40) -> 0 | X40: =sum(V40+W40) -> 0 | Y40: =sum(Formulas!AI37*'Daily Time Readings Log'!C40) -> 0 | Z40: =sum(Formulas!AJ37*'Daily Time Readings Log'!C40) -> 0 | AA40: =if((E40="None"),0,0) -> 0 | AB40: =if((AND(N40>1,E40="T")),1,0) -> 0 | AC40: =if((AND(N40>1,E40="M.P.")),1,0) -> 0 | AD40: =if((E40="BIO"),S40-AF40,0) -> 0 | AE40: =if((E40="L.A."),S40-AF40,0) -> 0 | AF40: =(L40/60) -> 0 | AG40: =if((E40="T"),Formulas!AG37,0) -> 0 | AH40: =if((AG40<1),AG40,1) -> 0 | AI40: =if((B40=0),0,AH40) -> 0 | AJ40: =if((E40="M.P."),Formulas!AG37,0) -> 0 | AK40: =if((AJ40<1),AJ40,1) -> 0 | AL40: =if((B40=0),0,AK40) -> 0 | AM40: =sum(AL40*B40) -> 0 | AN40: =if((E40="BIO"),N40,0) -> 0 | AO40: =sum(AN40*1) -> 0 | AP40: =if((AO40>0),(AO40-Formulas!AM37),0) -> 0 | AQ40: =if((E40="L.A."),N40,0) -> 0 | AR40: =sum(AQ40*1) -> 0 | AS40: =if((AR40>0),(AR40-Formulas!AM37),0) -> 0
S41: =sum(S6:S40) -> 0 | T41: =sum(T6:T40) -> 0 | U41: =sum(U6:U40) -> 0 | V41: =sum(V6:V40) -> 0 | W41: =sum(W6:W40) -> 0 | X41: =sum(X6:X40) -> 0 | Y41: =sum(Y6:Y40) -> 0 | Z41: =sum(Z6:Z40) -> 0 | ... AS41: =sum(AS6:AS40) -> 0
A43: Total days technician(s) present on jobsite | E43: =IFERROR(__xludf.DUMMYFUNCTION("COUNTUNIQUE(A6:A40,A6:A40)"),0.0) -> 0 | J43: Monitoring (During Hrs) | O43: =sum(S41-AI41-AM41-AP41-AS41) -> 0
A44: Total days technician(s) preformed check & service | E44: =if(E43>2,E43-2,"0") -> 0 | J44: Monitoring (After Hrs) | O44: =sum(T41) -> 0

Sheet General Log
J1: General Log
A2: Category: | D2: Input Category | J2: Entrusted
A3: Cause of Loss | J3: 10491 Fussel Rd | P3: Total pieces of equipment | T3: =sum(D26:D27) -> 0
A4: HC? | J4: Conroe, TX 77385
A5: Generals | D5: # | E5: Notes | P5: Dehu $ (Set up / take down) | T5: 29.23 | U5: =sum(D26) -> 0 | V5: =sum(T5*U5) -> 0
A6: Emergency Call During Hours (Each) | E6: =if(D6>0,"Project installed during business hours (8:30am - 5:00pm)","") | P6: Air Scrubber(Set up / take down) | T6: 14.62 | U6: =sum(D27) -> 0 | V6: =sum(T6*U6) -> 0
A7: Emergency Call After Hours (Each) | E7: =if(D7>0,"Project installed after business hours (5:00pm - 8:29am)","") | P7: Air Mover (Set up / take down) | T7: 14.62 | U7: =sum(#REF!) -> #REF! | V7: =sum(T7*U7) -> #REF!
A8: Jobsite / Equipment Monitoring (Daily) | D8: =SUM('Daily Time Readings Log'!E44) -> 0 | P8: Last Date | T8: =max('Daily Time Readings Log'!A6:A40) -> 0
A9: Thermal Imaging (Each) | E9: =if(D9>0,"Used to help establish the extent of damage, moisture mapping, and documentation","")
A10: Mold Testing (Each) | E10: =if(D10>0,"Entrusted recommends mold test to be performed at client's expense","")
A11: Lead Testing (Each) | E11: =if(D11>0,"Required by EPA - Property built prior to 1978","")
A12: Sub-Contractor Charge (Each)
A13: Plumber Charge (Each)
A14: POD (Each)
A15: POD Delivery/Pickup Charge (Each)
A16: Plastic (Sqft)
A17: Bubble Wrap (Sqft) | E17: =if(D17>0,"Used for personal protection","")
A18: Full Coveralls (Each) | E18: =if(D18>0,"Used for personal protection","")
A19: Full Face Respirator (Each) | E19: =if(D19>0,"Used for personal protection","")
A20: Half Face Respirator (Each) | E20: =if(D20>0,"Used for personal protection","")
A21: Disposable Gloves (Each) | E21: =if(D21>0,"Used for personal protection","")
A22: Heavy Duty Gloves (Each) | E22: =if(D22>0,"Used for personal protection","")
A23: Eye Protection (Each) | E23: =if(D23>0,"Used for personal protection","")
A24: Pickup Dump Charge (Each) | E24: =if(D24>0,"Used to dump debris removed from jobsite","")
A25: Dumpster Bag (Each) | E25: =if(D25>0,"Used to dump debris removed from jobsite","")
A26: Decontaminate Dehus (Each) | E26: =if(D26>0,"Disinfect each dehu before installing","")
A27: Decontaminate Air Scrubbers (Each) | E27: =if(D27>0,"Disinfect each air scrubber before installing","")
A28: Decontaminate Air Movers (Each) | E28: =if(D28>0,"Disinfect each air mover before installing","")
A29: Area Rug Re-Delivery (Each)
A30: Temp Sink Hookup (Each)
A31: Disposable Mask (Each) | E31: =if(D31>0,"Used for personal protection","")
A32: Lumber (2x4)
A33: Floor Protection (Sqft) | E33: =if(D33>0,"Used to protect floor from damage","")
A34: Matterport | E34: =if(D34>0,"Matterport completed for documentation","")
A35: Tool Rental
A36: Category Testing Strips
A37: Final cleaning | D37: 1 | E37: Leave jobsite broom swept / vacuum debris
A38: Ladder (Per Day)
A39: Other
A40: Notes
...

Sheet Note Log
H1: Note Log
H2: Entrusted
A5: Day 1:
A6: Day 2:
A7: Day 3:
A8: Day 4:
A9: Day 5:
A10: Day 6:
A11: Day 7:
A12: Day 8:
A13: Day 9:
A14: Day 10:
A15: Notes:
A16: Notice: Please be aware that the current logs were completed with a full assessment at the present time to the best of our abilities. In the event of any questions about items or amounts, please submit a written notification of such inquiry, and our quality assurance team will respond as soon as possible.

Sheet Formulas
F1: Start Day | G1: End Day | T1: Total Overtime After 5Pm | X1: Total Overtime Before 8:30 | Y1: If Weekend (1) | AE1: Total Work Hours | AF1: Total Work / Travel | AG1: Total Work Regular Hours | AH1: Total Work Overtime Hours | AI1: Regular Work/Travel | AJ1: Overtime Work/Travel | AR1: Travel Hours | AU1: Regular Pay | AV1: Overtime Pay | AW1: Total Pay
U2: Total Overtime Before 8:30am | AA2: Regular | AB2: Overtime | AC2: Regular | AD2: Overtime | AM2: Total Regular Travel | AN2: Total Overtime Travel | AO2: Including Weekend | AP2: Before 8:30 | AQ2: After 5pm | AS2: Regular Pay | AT2: Overtime Pay
F3: 0.35416667 | G3: 0.70833333 | H3: =sum('Daily Time Readings Log'!K6-'Daily Time Readings Log'!J6) -> 0 | I3: =sum(H3*24) -> 0 | J3: =if(I3>0,I3,(I3+24)) -> 24 | K3: =if('Daily Time Readings Log'!K6>G3,('Daily Time Readings Log'!K6-G3),0) -> 0 | L3: =sum(G3-'Daily Time Readings Log'!J6) -> 0.70833333 | M3: =sum(L3*24) -> 17 | N3: =if(I3<0,M3,0) -> 0 | O3: =abs(N3) -> 0 | P3: =if(N3<0,O3,0) -> 0 | Q3: =sum(P3+R3) -> 0 | R3: =if(O3>0,(AE3-O3),0) -> 0 | S3: =sum(K3*24) -> 0 | T3: =sum(Q3+S3) -> 0 | U3: =if('Daily Time Readings Log'!J6<F3,(F3-'Daily Time Readings Log'!J6),0) -> 0.35416667 | V3: =sum(U3*24) -> 8.5 | W3: =if('Daily Time Readings Log'!J6<F3,(AE3),V3) -> 24 | X3: =if(W3>V3,V3,W3) -> 8.5 | Y3: =IF(WEEKDAY('Daily Time Readings Log'!A6,2)>5,1,0) -> 1 | Z3: =sum(T3+X3) -> 8.5 | AA3: =sum(AE3-AB3) -> 0 | AB3: =if(Y3>0,AE3,Z3) -> 24 | AC3: =if(AA3<0,0,AA3) -> 0 | AD3: =if(AA3<0,(AA3+AB3),AB3) -> 24 | AE3: =abs(J3) -> 24 | AF3: =sum(AE3+AR3) -> 24 | AG3: =if(M3=0,0,AC3) -> 0 | AH3: =if(AG3<AA3,AA3,AD3) -> 24 | AI3: =sum(AG3+AM3) -> 0 | AJ3: =sum(AH3+AN3) -> 24 | AM3: =if(AO3>=1,0,AR3) -> 0 | AN3: =if(AO3>=1,AR3,0) -> 0 | AO3: =sum(AP3+AQ3+Y3) -> 2 | AP3: =if('Daily Time Readings Log'!J6<F3,1,0) -> 1 | AQ3: =if('Daily Time Readings Log'!J6>G3,1,0) -> 0 | AR3: =sum('Daily Time Readings Log'!L6/60) -> 0 | AS3: 55.39 | AT3: 83.17 | AU3: =sum('Daily Time Readings Log'!N6*AS3) -> 0 | AV3: =sum('Daily Time Readings Log'!O6*AT3) -> 0 | AW3: =sum(AU3+AV3) -> 0
F4: 0.35416667 | G4: 0.70833333 | H4: =sum('Daily Time Readings Log'!K7-'Daily Time Readings Log'!J7) -> 0 | I4: =sum(H4*24) -> 0 | J4: =if(I4>0,I4,(I4+24)) -> 24 | K4: =if('Daily Time Readings Log'!K7>G4,('Daily Time Readings Log'!K7-G4),0) -> 0 | L4: =sum(G4-'Daily Time Readings Log'!J7) -> 0.70833333 | M4: =sum(L4*24) -> 17 | N4: =if(I4<0,M4,0) -> 0 | O4: =abs(N4) -> 0 | P4: =if(N4<0,O4,0) -> 0 | Q4: =sum(P4+R4) -> 0 | R4: =if(O4>0,(AE4-O4),0) -> 0 | S4: =sum(K4*24) -> 0 | T4: =sum(Q4+S4) -> 0 | U4: =if('Daily Time Readings Log'!J7<F4,(F4-'Daily Time Readings Log'!J7),0) -> 0.35416667 | V4: =sum(U4*24) -> 8.5 | W4: =if('Daily Time Readings Log'!J7<F4,(AE4),V4) -> 24 | X4: =if(W4>V4,V4,W4) -> 8.5 | Y4: =IF(WEEKDAY('Daily Time Readings Log'!A7,2)>5,1,0) -> 1 | Z4: =sum(T4+X4) -> 8.5 | AA4: =sum(AE4-AB4) -> 0 | AB4: =if(Y4>0,AE4,Z4) -> 24 | AC4: =if(AA4<0,0,AA4) -> 0 | AD4: =if(AA4<0,(AA4+AB4),AB4) -> 24 | AE4: =abs(J4) -> 24 | AF4: =sum(AE4+AR4) -> 24 | AG4: =if(M4=0,0,AC4) -> 0 | AH4: =if(AG4<AA4,AA4,AD4) -> 24 | AI4: =sum(AG4+AM4) -> 0 | AJ4: =sum(AH4+AN4) -> 24 | AM4: =if(AO4>=1,0,AR4) -> 0 | AN4: =if(AO4>=1,AR4,0) -> 0 | AO4: =sum(AP4+AQ4+Y4) -> 2 | AP4: =if('Daily Time Readings Log'!J7<F4,1,0) -> 1 | AQ4: =if('Daily Time Readings Log'!J7>G4,1,0) -> 0 | AR4: =sum('Daily Time Readings Log'!L7/60) -> 0 | AS4: 55.39 | AT4: 83.17 | AU4: =sum('Daily Time Readings Log'!N7*AS4) -> 0 | AV4: =sum('Daily Time Readings Log'!O7*AT4) -> 0 | AW4: =sum(AU4+AV4) -> 0
F5: 0.35416667 | G5: 0.70833333 | H5: =sum('Daily Time Readings Log'!K8-'Daily Time Readings Log'!J8) -> 0 | I5: =sum(H5*24) -> 0 | J5: =if(I5>0,I5,(I5+24)) -> 24 | K5: =if('Daily Time Readings Log'!K8>G5,('Daily Time Readings Log'!K8-G5),0) -> 0 | L5: =sum(G5-'Daily Time Readings Log'!J8) -> 0.70833333 | M5: =sum(L5*24) -> 17 | N5: =if(I5<0,M5,0) -> 0 | O5: =abs(N5) -> 0 | P5: =if(N5<0,O5,0) -> 0 | Q5: =sum(P5+R5) -> 0 | R5: =if(O5>0,(AE5-O5),0) -> 0 | S5: =sum(K5*24) -> 0 | T5: =sum(Q5+S5) -> 0 | U5: =if('Daily Time Readings Log'!J8<F5,(F5-'Daily Time Readings Log'!J8),0) -> 0.35416667 | V5: =sum(U5*24) -> 8.5 | W5: =if('Daily Time Readings Log'!J8<F5,(AE5),V5) -> 24 | X5: =if(W5>V5,V5,W5) -> 8.5 | Y5: =IF(WEEKDAY('Daily Time Readings Log'!A8,2)>5,1,0) -> 1 | Z5: =sum(T5+X5) -> 8.5 | AA5: =sum(AE5-AB5) -> 0 | AB5: =if(Y5>0,AE5,Z5) -> 24 | AC5: =if(AA5<0,0,AA5) -> 0 | AD5: =if(AA5<0,(AA5+AB5),AB5) -> 24 | AE5: =abs(J5) -> 24 | AF5: =sum(AE5+AR5) -> 24 | AG5: =if(M5=0,0,AC5) -> 0 | AH5: =if(AG5<AA5,AA5,AD5) -> 24 | AI5: =sum(AG5+AM5) -> 0 | AJ5: =sum(AH5+AN5) -> 24 | AM5: =if(AO5>=1,0,AR5) -> 0 | AN5: =if(AO5>=1,AR5,0) -> 0 | AO5: =sum(AP5+AQ5+Y5) -> 2 | AP5: =if('Daily Time Readings Log'!J8<F5,1,0) -> 1 | AQ5: =if('Daily Time Readings Log'!J8>G5,1,0) -> 0 | AR5: =sum('Daily Time Readings Log'!L8/60) -> 0 | AS5: 55.39 | AT5: 83.17 | AU5: =sum('Daily Time Readings Log'!N8*AS5) -> 0 | AV5: =sum('Daily Time Readings Log'!O8*AT5) -> 0 | AW5: =sum(AU5+AV5) -> 0
F6: 0.35416667 | G6: 0.70833333 | H6: =sum('Daily Time Readings Log'!K9-'Daily Time Readings Log'!J9) -> 0 | I6: =sum(H6*24) -> 0 | J6: =if(I6>0,I6,(I6+24)) -> 24 | K6: =if('Daily Time Readings Log'!K9>G6,('Daily Time Readings Log'!K9-G6),0) -> 0 | L6: =sum(G6-'Daily Time Readings Log'!J9) -> 0.70833333 | M6: =sum(L6*24) -> 17 | N6: =if(I6<0,M6,0) -> 0 | O6: =abs(N6) -> 0 | P6: =if(N6<0,O6,0) -> 0 | Q6: =sum(P6+R6) -> 0 | R6: =if(O6>0,(AE6-O6),0) -> 0 | S6: =sum(K6*24) -> 0 | T6: =sum(Q6+S6) -> 0 | U6: =if('Daily Time Readings Log'!J9<F6,(F6-'Daily Time Readings Log'!J9),0) -> 0.35416667 | V6: =sum(U6*24) -> 8.5 | W6: =if('Daily Time Readings Log'!J9<F6,(AE6),V6) -> 24 | X6: =if(W6>V6,V6,W6) -> 8.5 | Y6: =IF(WEEKDAY('Daily Time Readings Log'!A9,2)>5,1,0) -> 1 | Z6: =sum(T6+X6) -> 8.5 | AA6: =sum(AE6-AB6) -> 0 | AB6: =if(Y6>0,AE6,Z6) -> 24 | AC6: =if(AA6<0,0,AA6) -> 0 | AD6: =if(AA6<0,(AA6+AB6),AB6) -> 24 | AE6: =abs(J6) -> 24 | AF6: =sum(AE6+AR6) -> 24 | AG6: =if(M6=0,0,AC6) -> 0 | AH6: =if(AG6<AA6,AA6,AD6) -> 24 | AI6: =sum(AG6+AM6) -> 0 | AJ6: =sum(AH6+AN6) -> 24 | AM6: =if(AO6>=1,0,AR6) -> 0 | AN6: =if(AO6>=1,AR6,0) -> 0 | AO6: =sum(AP6+AQ6+Y6) -> 2 | AP6: =if('Daily Time Readings Log'!J9<F6,1,0) -> 1 | AQ6: =if('Daily Time Readings Log'!J9>G6,1,0) -> 0 | AR6: =sum('Daily Time Readings Log'!L9/60) -> 0 | AS6: 55.39 | AT6: 83.17 | AU6: =sum('Daily Time Readings Log'!N9*AS6) -> 0 | AV6: =sum('Daily Time Readings Log'!O9*AT6) -> 0 | AW6: =sum(AU6+AV6) -> 0
F7: 0.35416667 | G7: 0.70833333 | H7: =sum('Daily Time Readings Log'!K10-'Daily Time Readings Log'!J10) -> 0 | I7: =sum(H7*24) -> 0 | J7: =if(I7>0,I7,(I7+24)) -> 24 | K7: =if('Daily Time Readings Log'!K10>G7,('Daily Time Readings Log'!K10-G7),0) -> 0 | L7: =sum(G7-'Daily Time Readings Log'!J10) -> 0.70833333 | M7: =sum(L7*24) -> 17 | N7: =if(I7<0,M7,0) -> 0 | O7: =abs(N7) -> 0 | P7: =if(N7<0,O7,0) -> 0 | Q7: =sum(P7+R7) -> 0 | R7: =if(O7>0,(AE7-O7),0) -> 0 | S7: =sum(K7*24) -> 0 | T7: =sum(Q7+S7) -> 0 | U7: =if('Daily Time Readings Log'!J10<F7,(F7-'Daily Time Readings Log'!J10),0) -> 0.35416667 | V7: =sum(U7*24) -> 8.5 | W7: =if('Daily Time Readings Log'!J10<F7,(AE7),V7) -> 24 | X7: =if(W7>V7,V7,W7) -> 8.5 | Y7: =IF(WEEKDAY('Daily Time Readings Log'!A10,2)>5,1,0) -> 1 | Z7: =sum(T7+X7) -> 8.5 | AA7: =sum(AE7-AB7) -> 0 | AB7: =if(Y7>0,AE7,Z7) -> 24 | AC7: =if(AA7<0,0,AA7) -> 0 | AD7: =if(AA7<0,(AA7+AB7),AB7) -> 24 | AE7: =abs(J7) -> 24 | AF7: =sum(AE7+AR7) -> 24 | AG7: =if(M7=0,0,AC7) -> 0 | AH7: =if(AG7<AA7,AA7,AD7) -> 24 | AI7: =sum(AG7+AM7) -> 0 | AJ7: =sum(AH7+AN7) -> 24 | AM7: =if(AO7>=1,0,AR7) -> 0 | AN7: =if(AO7>=1,AR7,0) -> 0 | AO7: =sum(AP7+AQ7+Y7) -> 2 | AP7: =if('Daily Time Readings Log'!J10<F7,1,0) -> 1 | AQ7: =if('Daily Time Readings Log'!J10>G7,1,0) -> 0 | AR7: =sum('Daily Time Readings Log'!L10/60) -> 0 | AS7: 55.39 | AT7: 83.17 | AU7: =sum('Daily Time Readings Log'!N10*AS7) -> 0 | AV7: =sum('Daily Time Readings Log'!O10*AT7) -> 0 | AW7: =sum(AU7+AV7) -> 0
F8: 0.35416667 | G8: 0.70833333 | H8: =sum('Daily Time Readings Log'!K11-'Daily Time Readings Log'!J11) -> 0 | I8: =sum(H8*24) -> 0 | J8: =if(I8>0,I8,(I8+24)) -> 24 | K8: =if('Daily Time Readings Log'!K11>G8,('Daily Time Readings Log'!K11-G8),0) -> 0 | L8: =sum(G8-'Daily Time Readings Log'!J11) -> 0.70833333 | M8: =sum(L8*24) -> 17 | N8: =if(I8<0,M8,0) -> 0 | O8: =abs(N8) -> 0 | P8: =if(N8<0,O8,0) -> 0 | Q8: =sum(P8+R8) -> 0 | R8: =if(O8>0,(AE8-O8),0) -> 0 | S8: =sum(K8*24) -> 0 | T8: =sum(Q8+S8) -> 0 | U8: =if('Daily Time Readings Log'!J11<F8,(F8-'Daily Time Readings Log'!J11),0) -> 0.35416667 | V8: =sum(U8*24) -> 8.5 | W8: =if('Daily Time Readings Log'!J11<F8,(AE8),V8) -> 24 | X8: =if(W8>V8,V8,W8) -> 8.5 | Y8: =IF(WEEKDAY('Daily Time Readings Log'!A11,2)>5,1,0) -> 1 | Z8: =sum(T8+X8) -> 8.5 | AA8: =sum(AE8-AB8) -> 0 | AB8: =if(Y8>0,AE8,Z8) -> 24 | AC8: =if(AA8<0,0,AA8) -> 0 | AD8: =if(AA8<0,(AA8+AB8),AB8) -> 24 | AE8: =abs(J8) -> 24 | AF8: =sum(AE8+AR8) -> 24 | AG8: =if(M8=0,0,AC8) -> 0 | AH8: =if(AG8<AA8,AA8,AD8) -> 24 | AI8: =sum(AG8+AM8) -> 0 | AJ8: =sum(AH8+AN8) -> 24 | AM8: =if(AO8>=1,0,AR8) -> 0 | AN8: =if(AO8>=1,AR8,0) -> 0 | AO8: =sum(AP8+AQ8+Y8) -> 2 | AP8: =if('Daily Time Readings Log'!J11<F8,1,0) -> 1 | AQ8: =if('Daily Time Readings Log'!J11>G8,1,0) -> 0 | AR8: =sum('Daily Time Readings Log'!L11/60) -> 0 | AS8: 55.39 | AT8: 83.17 | AU8: =sum('Daily Time Readings Log'!N11*AS8) -> 0 | AV8: =sum('Daily Time Readings Log'!O11*AT8) -> 0 | AW8: =sum(AU8+AV8) -> 0
F9: 0.35416667 | G9: 0.70833333 | H9: =sum('Daily Time Readings Log'!K12-'Daily Time Readings Log'!J12) -> 0 | I9: =sum(H9*24) -> 0 | J9: =if(I9>0,I9,(I9+24)) -> 24 | K9: =if('Daily Time Readings Log'!K12>G9,('Daily Time Readings Log'!K12-G9),0) -> 0 | L9: =sum(G9-'Daily Time Readings Log'!J12) -> 0.70833333 | M9: =sum(L9*24) -> 17 | N9: =if(I9<0,M9,0) -> 0 | O9: =abs(N9) -> 0 | P9: =if(N9<0,O9,0) -> 0 | Q9: =sum(P9+R9) -> 0 | R9: =if(O9>0,(AE9-O9),0) -> 0 | S9: =sum(K9*24) -> 0 | T9: =sum(Q9+S9) -> 0 | U9: =if('Daily Time Readings Log'!J12<F9,(F9-'Daily Time Readings Log'!J12),0) -> 0.35416667 | V9: =sum(U9*24) -> 8.5 | W9: =if('Daily Time Readings Log'!J12<F9,(AE9),V9) -> 24 | X9: =if(W9>V9,V9,W9) -> 8.5 | Y9: =IF(WEEKDAY('Daily Time Readings Log'!A12,2)>5,1,0) -> 1 | Z9: =sum(T9+X9) -> 8.5 | AA9: =sum(AE9-AB9) -> 0 | AB9: =if(Y9>0,AE9,Z9) -> 24 | AC9: =if(AA9<0,0,AA9) -> 0 | AD9: =if(AA9<0,(AA9+AB9),AB9) -> 24 | AE9: =abs(J9) -> 24 | AF9: =sum(AE9+AR9) -> 24 | AG9: =if(M9=0,0,AC9) -> 0 | AH9: =if(AG9<AA9,AA9,AD9) -> 24 | AI9: =sum(AG9+AM9) -> 0 | AJ9: =sum(AH9+AN9) -> 24 | AM9: =if(AO9>=1,0,AR9) -> 0 | AN9: =if(AO9>=1,AR9,0) -> 0 | AO9: =sum(AP9+AQ9+Y9) -> 2 | AP9: =if('Daily Time Readings Log'!J12<F9,1,0) -> 1 | AQ9: =if('Daily Time Readings Log'!J12>G9,1,0) -> 0 | AR9: =sum('Daily Time Readings Log'!L12/60) -> 0 | AS9: 55.39 | AT9: 83.17 | AU9: =sum('Daily Time Readings Log'!N12*AS9) -> 0 | AV9: =sum('Daily Time Readings Log'!O12*AT9) -> 0 | AW9: =sum(AU9+AV9) -> 0
F10: 0.35416667 | G10: 0.70833333 | H10: =sum('Daily Time Readings Log'!K13-'Daily Time Readings Log'!J13) -> 0 | I10: =sum(H10*24) -> 0 | J10: =if(I10>0,I10,(I10+24)) -> 24 | K10: =if('Daily Time Readings Log'!K13>G10,('Daily Time Readings Log'!K13-G10),0) -> 0 | L10: =sum(G10-'Daily Time Readings Log'!J13) -> 0.70833333 | M10: =sum(L10*24) -> 17 | N10: =if(I10<0,M10,0) -> 0 | O10: =abs(N10) -> 0 | P10: =if(N10<0,O10,0) -> 0 | Q10: =sum(P10+R10) -> 0 | R10: =if(O10>0,(AE10-O10),0) -> 0 | S10: =sum(K10*24) -> 0 | T10: =sum(Q10+S10) -> 0 | U10: =if('Daily Time Readings Log'!J13<F10,(F10-'Daily Time Readings Log'!J13),0) -> 0.35416667 | V10: =sum(U10*24) -> 8.5 | W10: =if('Daily Time Readings Log'!J13<F10,(AE10),V10) -> 24 | X10: =if(W10>V10,V10,W10) -> 8.5 | Y10: =IF(WEEKDAY('Daily Time Readings Log'!A13,2)>5,1,0) -> 1 | Z10: =sum(T10+X10) -> 8.5 | AA10: =sum(AE10-AB10) -> 0 | AB10: =if(Y10>0,AE10,Z10) -> 24 | AC10: =if(AA10<0,0,AA10) -> 0 | AD10: =if(AA10<0,(AA10+AB10),AB10) -> 24 | AE10: =abs(J10) -> 24 | AF10: =sum(AE10+AR10) -> 24 | AG10: =if(M10=0,0,AC10) -> 0 | AH10: =if(AG10<AA10,AA10,AD10) -> 24 | AI10: =sum(AG10+AM10) -> 0 | AJ10: =sum(AH10+AN10) -> 24 | AM10: =if(AO10>=1,0,AR10) -> 0 | AN10: =if(AO10>=1,AR10,0) -> 0 | AO10: =sum(AP10+AQ10+Y10) -> 2 | AP10: =if('Daily Time Readings Log'!J13<F10,1,0) -> 1 | AQ10: =if('Daily Time Readings Log'!J13>G10,1,0) -> 0 | AR10: =sum('Daily Time Readings Log'!L13/60) -> 0 | AS10: 55.39 | AT10: 83.17 | AU10: =sum('Daily Time Readings Log'!N13*AS10) -> 0 | AV10: =sum('Daily Time Readings Log'!O13*AT10) -> 0 | AW10: =sum(AU10+AV10) -> 0
F11: 0.35416667 | G11: 0.70833333 | H11: =sum('Daily Time Readings Log'!K14-'Daily Time Readings Log'!J14) -> 0 | I11: =sum(H11*24) -> 0 | J11: =if(I11>0,I11,(I11+24)) -> 24 | K11: =if('Daily Time Readings Log'!K14>G11,('Daily Time Readings Log'!K14-G11),0) -> 0 | L11: =sum(G11-'Daily Time Readings Log'!J14) -> 0.70833333 | M11: =sum(L11*24) -> 17 | N11: =if(I11<0,M11,0) -> 0 | O11: =abs(N11) -> 0 | P11: =if(N11<0,O11,0) -> 0 | Q11: =sum(P11+R11) -> 0 | R11: =if(O11>0,(AE11-O11),0) -> 0 | S11: =sum(K11*24) -> 0 | T11: =sum(Q11+S11) -> 0 | U11: =if('Daily Time Readings Log'!J14<F11,(F11-'Daily Time Readings Log'!J14),0) -> 0.35416667 | V11: =sum(U11*24) -> 8.5 | W11: =if('Daily Time Readings Log'!J14<F11,(AE11),V11) -> 24 | X11: =if(W11>V11,V11,W11) -> 8.5 | Y11: =IF(WEEKDAY('Daily Time Readings Log'!A14,2)>5,1,0) -> 1 | Z11: =sum(T11+X11) -> 8.5 | AA11: =sum(AE11-AB11) -> 0 | AB11: =if(Y11>0,AE11,Z11) -> 24 | AC11: =if(AA11<0,0,AA11) -> 0 | AD11: =if(AA11<0,(AA11+AB11),AB11) -> 24 | AE11: =abs(J11) -> 24 | AF11: =sum(AE11+AR11) -> 24 | AG11: =if(M11=0,0,AC11) -> 0 | AH11: =if(AG11<AA11,AA11,AD11) -> 24 | AI11: =sum(AG11+AM11) -> 0 | AJ11: =sum(AH11+AN11) -> 24 | AM11: =if(AO11>=1,0,AR11) -> 0 | AN11: =if(AO11>=1,AR11,0) -> 0 | AO11: =sum(AP11+AQ11+Y11) -> 2 | AP11: =if('Daily Time Readings Log'!J14<F11,1,0) -> 1 | AQ11: =if('Daily Time Readings Log'!J14>G11,1,0) -> 0 | AR11: =sum('Daily Time Readings Log'!L14/60) -> 0 | AS11: 55.39 | AT11: 83.17 | AU11: =sum('Daily Time Readings Log'!N14*AS11) -> 0 | AV11: =sum('Daily Time Readings Log'!O14*AT11) -> 0 | AW11: =sum(AU11+AV11) -> 0
F12: 0.35416667 | G12: 0.70833333 | H12: =sum('Daily Time Readings Log'!K15-'Daily Time Readings Log'!J15) -> 0 | I12: =sum(H12*24) -> 0 | J12: =if(I12>0,I12,(I12+24)) -> 24 | K12: =if('Daily Time Readings Log'!K15>G12,('Daily Time Readings Log'!K15-G12),0) -> 0 | L12: =sum(G12-'Daily Time Readings Log'!J15) -> 0.70833333 | M12: =sum(L12*24) -> 17 | N12: =if(I12<0,M12,0) -> 0 | O12: =abs(N12) -> 0 | P12: =if(N12<0,O12,0) -> 0 | Q12: =sum(P12+R12) -> 0 | R12: =if(O12>0,(AE12-O12),0) -> 0 | S12: =sum(K12*24) -> 0 | T12: =sum(Q12+S12) -> 0 | U12: =if('Daily Time Readings Log'!J15<F12,(F12-'Daily Time Readings Log'!J15),0) -> 0.35416667 | V12: =sum(U12*24) -> 8.5 | W12: =if('Daily Time Readings Log'!J15<F12,(AE12),V12) -> 24 | X12: =if(W12>V12,V12,W12) -> 8.5 | Y12: =IF(WEEKDAY('Daily Time Readings Log'!A15,2)>5,1,0) -> 1 | Z12: =sum(T12+X12) -> 8.5 | AA12: =sum(AE12-AB12) -> 0 | AB12: =if(Y12>0,AE12,Z12) -> 24 | AC12: =if(AA12<0,0,AA12) -> 0 | AD12: =if(AA12<0,(AA12+AB12),AB12) -> 24 | AE12: =abs(J12) -> 24 | AF12: =sum(AE12+AR12) -> 24 | AG12: =if(M12=0,0,AC12) -> 0 | AH12: =if(AG12<AA12,AA12,AD12) -> 24 | AI12: =sum(AG12+AM12) -> 0 | AJ12: =sum(AH12+AN12) -> 24 | AM12: =if(AO12>=1,0,AR12) -> 0 | AN12: =if(AO12>=1,AR12,0) -> 0 | AO12: =sum(AP12+AQ12+Y12) -> 2 | AP12: =if('Daily Time Readings Log'!J15<F12,1,0) -> 1 | AQ12: =if('Daily Time Readings Log'!J15>G12,1,0) -> 0 | AR12: =sum('Daily Time Readings Log'!L15/60) -> 0 | AS12: 55.39 | AT12: 83.17 | AU12: =sum('Daily Time Readings Log'!N15*AS12) -> 0 | AV12: =sum('Daily Time Readings Log'!O15*AT12) -> 0 | AW12: =sum(AU12+AV12) -> 0
F13: 0.35416667 | G13: 0.70833333 | H13: =sum('Daily Time Readings Log'!K16-'Daily Time Readings Log'!J16) -> 0 | I13: =sum(H13*24) -> 0 | J13: =if(I13>0,I13,(I13+24)) -> 24 | K13: =if('Daily Time Readings Log'!K16>G13,('Daily Time Readings Log'!K16-G13),0) -> 0 | L13: =sum(G13-'Daily Time Readings Log'!J16) -> 0.70833333 | M13: =sum(L13*24) -> 17 | N13: =if(I13<0,M13,0) -> 0 | O13: =abs(N13) -> 0 | P13: =if(N13<0,O13,0) -> 0 | Q13: =sum(P13+R13) -> 0 | R13: =if(O13>0,(AE13-O13),0) -> 0 | S13: =sum(K13*24) -> 0 | T13: =sum(Q13+S13) -> 0 | U13: =if('Daily Time Readings Log'!J16<F13,(F13-'Daily Time Readings Log'!J16),0) -> 0.35416667 | V13: =sum(U13*24) -> 8.5 | W13: =if('Daily Time Readings Log'!J16<F13,(AE13),V13) -> 24 | X13: =if(W13>V13,V13,W13) -> 8.5 | Y13: =IF(WEEKDAY('Daily Time Readings Log'!A16,2)>5,1,0) -> 1 | Z13: =sum(T13+X13) -> 8.5 | AA13: =sum(AE13-AB13) -> 0 | AB13: =if(Y13>0,AE13,Z13) -> 24 | AC13: =if(AA13<0,0,AA13) -> 0 | AD13: =if(AA13<0,(AA13+AB13),AB13) -> 24 | AE13: =abs(J13) -> 24 | AF13: =sum(AE13+AR13) -> 24 | AG13: =if(M13=0,0,AC13) -> 0 | AH13: =if(AG13<AA13,AA13,AD13) -> 24 | AI13: =sum(AG13+AM13) -> 0 | AJ13: =sum(AH13+AN13) -> 24 | AM13: =if(AO13>=1,0,AR13) -> 0 | AN13: =if(AO13>=1,AR13,0) -> 0 | AO13: =sum(AP13+AQ13+Y13) -> 2 | AP13: =if('Daily Time Readings Log'!J16<F13,1,0) -> 1 | AQ13: =if('Daily Time Readings Log'!J16>G13,1,0) -> 0 | AR13: =sum('Daily Time Readings Log'!L16/60) -> 0 | AS13: 55.39 | AT13: 83.17 | AU13: =sum('Daily Time Readings Log'!N16*AS13) -> 0 | AV13: =sum('Daily Time Readings Log'!O16*AT13) -> 0 | AW13: =sum(AU13+AV13) -> 0
F14: 0.35416667 | G14: 0.70833333 | H14: =sum('Daily Time Readings Log'!K17-'Daily Time Readings Log'!J17) -> 0 | I14: =sum(H14*24) -> 0 | J14: =if(I14>0,I14,(I14+24)) -> 24 | K14: =if('Daily Time Readings Log'!K17>G14,('Daily Time Readings Log'!K17-G14),0) -> 0 | L14: =sum(G14-'Daily Time Readings Log'!J17) -> 0.70833333 | M14: =sum(L14*24) -> 17 | N14: =if(I14<0,M14,0) -> 0 | O14: =abs(N14) -> 0 | P14: =if(N14<0,O14,0) -> 0 | Q14: =sum(P14+R14) -> 0 | R14: =if(O14>0,(AE14-O14),0) -> 0 | S14: =sum(K14*24) -> 0 | T14: =sum(Q14+S14) -> 0 | U14: =if('Daily Time Readings Log'!J17<F14,(F14-'Daily Time Readings Log'!J17),0) -> 0.35416667 | V14: =sum(U14*24) -> 8.5 | W14: =if('Daily Time Readings Log'!J17<F14,(AE14),V14) -> 24 | X14: =if(W14>V14,V14,W14) -> 8.5 | Y14: =IF(WEEKDAY('Daily Time Readings Log'!A17,2)>5,1,0) -> 1 | Z14: =sum(T14+X14) -> 8.5 | AA14: =sum(AE14-AB14) -> 0 | AB14: =if(Y14>0,AE14,Z14) -> 24 | AC14: =if(AA14<0,0,AA14) -> 0 | AD14: =if(AA14<0,(AA14+AB14),AB14) -> 24 | AE14: =abs(J14) -> 24 | AF14: =sum(AE14+AR14) -> 24 | AG14: =if(M14=0,0,AC14) -> 0 | AH14: =if(AG14<AA14,AA14,AD14) -> 24 | AI14: =sum(AG14+AM14) -> 0 | AJ14: =sum(AH14+AN14) -> 24 | AM14: =if(AO14>=1,0,AR14) -> 0 | AN14: =if(AO14>=1,AR14,0) -> 0 | AO14: =sum(AP14+AQ14+Y14) -> 2 | AP14: =if('Daily Time Readings Log'!J17<F14,1,0) -> 1 | AQ14: =if('Daily Time Readings Log'!J17>G14,1,0) -> 0 | AR14: =sum('Daily Time Readings Log'!L17/60) -> 0 | AS14: 55.39 | AT14: 83.17 | AU14: =sum('Daily Time Readings Log'!N17*AS14) -> 0 | AV14: =sum('Daily Time Readings Log'!O17*AT14) -> 0 | AW14: =sum(AU14+AV14) -> 0
... F37: 0.35416667 | G37: 0.70833333 | H37: =sum('Daily Time Readings Log'!K40-'Daily Time Readings Log'!J40) -> 0 | I37: =sum(H37*24) -> 0 | J37: =if(I37>0,I37,(I37+24)) -> 24 | K37: =if('Daily Time Readings Log'!K40>G37,('Daily Time Readings Log'!K40-G37),0) -> 0 | L37: =sum(G37-'Daily Time Readings Log'!J40) -> 0.70833333 | M37: =sum(L37*24) -> 17 | N37: =if(I37<0,M37,0) -> 0 | O37: =abs(N37) -> 0 | P37: =if(N37<0,O37,0) -> 0 | Q37: =sum(P37+R37) -> 0 | R37: =if(O37>0,(AE37-O37),0) -> 0 | S37: =sum(K37*24) -> 0 | T37: =sum(Q37+S37) -> 0 | U37: =if('Daily Time Readings Log'!J40<F37,(F37-'Daily Time Readings Log'!J40),0) -> 0.35416667 | V37: =sum(U37*24) -> 8.5 | W37: =if('Daily Time Readings Log'!J40<F37,(AE37),V37) -> 24 | X37: =if(W37>V37,V37,W37) -> 8.5 | Y37: =IF(WEEKDAY('Daily Time Readings Log'!A40,2)>5,1,0) -> 1 | Z37: =sum(T37+X37) -> 8.5 | AA37: =sum(AE37-AB37) -> 0 | AB37: =if(Y37>0,AE37,Z37) -> 24 | AC37: =if(AA37<0,0,AA37) -> 0 | AD37: =if(AA37<0,(AA37+AB37),AB37) -> 24 | AE37: =abs(J37) -> 24 | AF37: =sum(AE37+AR37) -> 24 | AG37: =if(M37=0,0,AC37) -> 0 | AH37: =if(AG37<AA37,AA37,AD37) -> 24 | AI37: =sum(AG37+AM37) -> 0 | AJ37: =sum(AH37+AN37) -> 24 | AM37: =if(AO37>=1,0,AR37) -> 0 | AN37: =if(AO37>=1,AR37,0) -> 0 | AO37: =sum(AP37+AQ37+Y37) -> 2 | AP37: =if('Daily Time Readings Log'!J40<F37,1,0) -> 1 | AQ37: =if('Daily Time Readings Log'!J40>G37,1,0) -> 0 | AR37: =sum('Daily Time Readings Log'!L40/60) -> 0 | AS37: 55.39 | AT37: 83.17 | AU37: =sum('Daily Time Readings Log'!N40*AS37) -> 0 | AV37: =sum('Daily Time Readings Log'!O40*AT37) -> 0 | AW37: =sum(AU37+AV37) -> 0

Sheet Scratch Pad
E1: Rooms added | F1: Room Actions | G1: Actual Rooms
E2: Current room | F2: Add Selected Rooms | G2: =E2 -> Current room
A3: Class | B3: =sum(#REF!) -> #REF! | C3: =if(B3=1,"100",If(B3=2,"50",If(B3=3,"40",if(B3=4,"40","0")))) -> #REF! | E3: No dehu needed | F3: Add Custom Room | G3: =E3 -> No dehu needed
E4: Kitchen | F4: - Select Action - | G4: =IF(ISERROR(INDIRECT(E4&"!A1")), "", E4)
A5: Sheet Name: | C5: Cubic Volume: | G5: =IF(ISERROR(INDIRECT(E5&"!A1")), "", E5)
G6: =IF(ISERROR(INDIRECT(E6&"!A1")), "", E6)
B7: =IFERROR(__xludf.DUMMYFUNCTION("IF(TODAY()=TODAY(), REGEXREPLACE(CELL(""address"",Template!A3),""'?([^']+)'?!.*"",""$1""), """")"),"Template") -> Template | C7: =sum(Template!P9) -> 0 | G7: =IF(ISERROR(INDIRECT(E7&"!A1")), "", E7)
B8: =IFERROR(__xludf.DUMMYFUNCTION("IF(TODAY()=TODAY(), REGEXREPLACE(CELL(""address"",ZZ!A2),""'?([^']+)'?!.*"",""$1""), """")"),"#REF!") -> #REF! | C8: =sum(ZZ!O9) -> #REF! | G8: =IF(ISERROR(INDIRECT(E8&"!A1")), "", E8)
B9: =IFERROR(__xludf.DUMMYFUNCTION("IF(TODAY()=TODAY(), REGEXREPLACE(CELL(""address"",ZZZ!A3),""'?([^']+)'?!.*"",""$1""), """")"),"#REF!") -> #REF! | C9: =sum(ZZZ!O9) -> #REF! | G9: =IF(ISERROR(INDIRECT(E9&"!A1")), "", E9)
B10: =IFERROR(__xludf.DUMMYFUNCTION("IF(TODAY()=TODAY(), REGEXREPLACE(CELL(""address"",ZZZZ!A4),""'?([^']+)'?!.*"",""$1""), """")"),"#REF!") -> #REF! | C10: =sum(ZZZZZ!O9) -> #REF! | G10: =IF(ISERROR(INDIRECT(E10&"!A1")), "", E10)
B11: =IFERROR(__xludf.DUMMYFUNCTION("IF(TODAY()=TODAY(), REGEXREPLACE(CELL(""address"",ZZZZZ!A5),""'?([^']+)'?!.*"",""$1""), """")"),"#REF!") -> #REF! | C11: =sum(ZZZZZ!O9) -> #REF! | G11: =IF(ISERROR(INDIRECT(E11&"!A1")), "", E11)
B12: =IFERROR(__xludf.DUMMYFUNCTION("IF(TODAY()=TODAY(), REGEXREPLACE(CELL(""address"",ZZZZZZ!A6),""'?([^']+)'?!.*"",""$1""), """")"),"#REF!") -> #REF! | C12: =sum(ZZZZZZ!O9) -> #REF! | G12: =IF(ISERROR(INDIRECT(E12&"!A1")), "", E12)
B13: =IFERROR(__xludf.DUMMYFUNCTION("IF(TODAY()=TODAY(), REGEXREPLACE(CELL(""address"",ZZZZZZZ!A7),""'?([^']+)'?!.*"",""$1""), """")"),"#REF!") -> #REF! | C13: =sum(ZZZZZZZ!O9) -> #REF! | G13: =IF(ISERROR(INDIRECT(E13&"!A1")), "", E13)
B14: =IFERROR(__xludf.DUMMYFUNCTION("IF(TODAY()=TODAY(), REGEXREPLACE(CELL(""address"",ZZZZZZZZ!A8),""'?([^']+)'?!.*"",""$1""), """")"),"#REF!") -> #REF! | C14: =sum(ZZZZZZZZZ!O9) -> #REF! | G14: =IF(ISERROR(INDIRECT(E14&"!A1")), "", E14)
B15: =IFERROR(__xludf.DUMMYFUNCTION("IF(TODAY()=TODAY(), REGEXREPLACE(CELL(""address"",ZZZZZZZZZ!A9),""'?([^']+)'?!.*"",""$1""), """")"),"#REF!") -> #REF! | C15: =sum(ZZZZZZZZZZ!O9) -> #REF! | G15: =IF(ISERROR(INDIRECT(E15&"!A1")), "", E15)
B16: =IFERROR(__xludf.DUMMYFUNCTION("IF(TODAY()=TODAY(), REGEXREPLACE(CELL(""address"",ZZZZZZZZZZ!A10),""'?([^']+)'?!.*"",""$1""), """")"),"#REF!") -> #REF! | C16: =sum(ZZZZZZZZZZZ!O9) -> #REF! | G16: =IF(ISERROR(INDIRECT(E16&"!A1")), "", E16)
B17: None | C17: 0 | G17: =IF(ISERROR(INDIRECT(E17&"!A1")), "", E17)
G18: =IF(ISERROR(INDIRECT(E18&"!A1")), "", E18)
G19: =IF(ISERROR(INDIRECT(E19&"!A1")), "", E19)
A20: Drop Menu: | B20: None | G20: =IF(ISERROR(INDIRECT(E20&"!A1")), "", E20)
G21: =IF(ISERROR(INDIRECT(E21&"!A1")), "", E21)
G22: =IF(ISERROR(INDIRECT(E22&"!A1")), "", E22)
A23: Drymax: | B23: 80 | G23: =IF(ISERROR(INDIRECT(E23&"!A1")), "", E23)
A24: 7000: | B24: 130 | G24: =IF(ISERROR(INDIRECT(E24&"!A1")), "", E24)
G25: =IF(ISERROR(INDIRECT(E25&"!A1")), "", E25)
G26: =IF(ISERROR(INDIRECT(E26&"!A1")), "", E26)
G27: =IF(ISERROR(INDIRECT(E27&"!A1")), "", E27)
G28: =IF(ISERROR(INDIRECT(E28&"!A1")), "", E28)
G29: =IF(ISERROR(INDIRECT(E29&"!A1")), "", E29)
G30: =IF(ISERROR(INDIRECT(E30&"!A1")), "", E30)
G31: =IF(ISERROR(INDIRECT(E31&"!A1")), "", E31)
G32: =IF(ISERROR(INDIRECT(E32&"!A1")), "", E32)
G33: =IF(ISERROR(INDIRECT(E33&"!A1")), "", E33)
G34: =IF(ISERROR(INDIRECT(E34&"!A1")), "", E34)
G35: =IF(ISERROR(INDIRECT(E35&"!A1")), "", E35)
G36: =IF(ISERROR(INDIRECT(E36&"!A1")), "", E36)
... G200: =IF(ISERROR(INDIRECT(E200&"!A1")), "", E200)

Sheet Template
I1: Room Log
I2: Entrusted
A3: Room: | C3: =sheetname(D4) -> #NAME? | E3: Drying Chamber | H3: 1
A4: Room Size: | C4: Length | E4: Width | G4: Height
A5: Material | B5: Dry Standard | C5: Day 1 | D5: Day 2 | E5: Day 3 | F5: Day 4 | G5: Day 5 | H5: Day 6 | I5: Day 7 | J5: Day 8 | K5: Day 9 | L5: Day 10 | O5: Drymax Total | P5: =sum(K13:K14) -> 0 | Q5: 80 | R5: =sum(P5*Q5) -> 0 | T5: All Rooms | U5: Dehu Accomplised by | V5: Add CF to this room
O6: 7000 Total | P6: =sum(K15:K16) -> 0 | Q6: 130 | R6: =sum(P6*Q6) -> 0 | T6: ='Scratch Pad'!G4 | U6: =IF(EQ(T6, ""), "", INDIRECT(T6&"!E3")) | V6: =if(AND(NE(T6, ""), EQ($C$3, U6)), INDIRECT(T6&"!P9"), 0) -> #NAME?
O7: Total Dehu and Rating | P7: =sum(P5:P6) -> 0 | R7: =sum(R5:R6) -> 0 | T7: ='Scratch Pad'!G5 | U7: =IF(EQ(T7, ""), "", INDIRECT(T7&"!E3")) | V7: =if(AND(NE(T7, ""), EQ($C$3, U7)), INDIRECT(T7&"!P9"), 0) -> #NAME?
T8: ='Scratch Pad'!G6 | U8: =IF(EQ(T8, ""), "", INDIRECT(T8&"!E3")) | V8: =if(AND(NE(T8, ""), EQ($C$3, U8)), INDIRECT(T8&"!P9"), 0) -> #NAME?
O9: Cubic Volume Room | P9: =sum(D4*F4*H4) -> 0 | T9: ='Scratch Pad'!G7 | U9: =IF(EQ(T9, ""), "", INDIRECT(T9&"!E3")) | V9: =if(AND(NE(T9, ""), EQ($C$3, U9)), INDIRECT(T9&"!P9"), 0) -> #NAME?
O10: Added Rooms | P10: =SUM(V6:V214) -> #NAME? | T10: ='Scratch Pad'!G8 | U10: =IF(EQ(T10, ""), "", INDIRECT(T10&"!E3")) | V10: =if(AND(NE(T10, ""), EQ($C$3, U10)), INDIRECT(T10&"!P9"), 0) -> #NAME?
O11: Total Shared Volume | P11: =sum(P9:P10) -> #NAME? | T11: ='Scratch Pad'!G9 | U11: =IF(EQ(T11, ""), "", INDIRECT(T11&"!E3")) | V11: =if(AND(NE(T11, ""), EQ($C$3, U11)), INDIRECT(T11&"!P9"), 0) -> #NAME?
A12: (Y or N) | B12: Removal Line Items | E12: SQFT | F12: After Hrs | H12: Air Mover Calculation | L12: FALSE | T12: ='Scratch Pad'!G10 | U12: =IF(EQ(T12, ""), "", INDIRECT(T12&"!E3")) | V12: =if(AND(NE(T12, ""), EQ($C$3, U12)), INDIRECT(T12&"!P9"), 0) -> #NAME?
A13: FALSE | B13: Flooring | F13: FALSE | H13: Initial air mover | L13: =if(L12=FALSE,"",1) | T13: ='Scratch Pad'!G11 | U13: =IF(EQ(T13, ""), "", INDIRECT(T13&"!E3")) | V13: =if(AND(NE(T13, ""), EQ($C$3, U13)), INDIRECT(T13&"!P9"), 0) -> #NAME?
A14: FALSE | B14: Flooring | F14: FALSE | H14: Affected flooring (sqft) | T14: ='Scratch Pad'!G12 | U14: =IF(EQ(T14, ""), "", INDIRECT(T14&"!E3")) | V14: =if(AND(NE(T14, ""), EQ($C$3, U14)), INDIRECT(T14&"!P9"), 0) -> #NAME?
A15: FALSE | B15: Add Glue Down (Flooring) | F15: FALSE | H15: Affected ceiling / walls above 24 in. (sqft) | O15: Class Calculation | P15: =('Scratch Pad'!C$3) -> #REF! | T15: ='Scratch Pad'!G13 | U15: =IF(EQ(T15, ""), "", INDIRECT(T15&"!E3")) | V15: =if(AND(NE(T15, ""), EQ($C$3, U15)), INDIRECT(T15&"!P9"), 0) -> #NAME?
A16: FALSE | B16: Tile Walls | F16: FALSE | H16: Insets / offsets > 18 in. (each) | L16: 0 | T16: ='Scratch Pad'!G14 | U16: =IF(EQ(T16, ""), "", INDIRECT(T16&"!E3")) | V16: =if(AND(NE(T16, ""), EQ($C$3, U16)), INDIRECT(T16&"!P9"), 0) -> #NAME?
A17: FALSE | B17: Baseboards | F17: FALSE | H17: Recommended Amount of Air Movers | L17: =if(P31=0,"",P31) | T17: ='Scratch Pad'!G15 | U17: =IF(EQ(T17, ""), "", INDIRECT(T17&"!E3")) | V17: =if(AND(NE(T17, ""), EQ($C$3, U17)), INDIRECT(T17&"!P9"), 0) -> #NAME?
A18: FALSE | B18: Trimwork | F18: FALSE | H18: Equip. | I18: Installed | J18: Amount | K18: Days | L18: Pulled | O18: Cleaning | P18: =countif(A13:A31,TRUE) -> 0 | T18: ='Scratch Pad'!G16 | U18: =IF(EQ(T18, ""), "", INDIRECT(T18&"!E3")) | V18: =if(AND(NE(T18, ""), EQ($C$3, U18)), INDIRECT(T18&"!P9"), 0) -> #NAME?
A19: FALSE | B19: Drywall | F19: FALSE | H19: A.M. (D) | O19: AHAM Calculation | P19: =sum(P11/P15) -> #NAME? | T19: ='Scratch Pad'!G17 | U19: =IF(EQ(T19, ""), "", INDIRECT(T19&"!E3")) | V19: =if(AND(NE(T19, ""), EQ($C$3, U19)), INDIRECT(T19&"!P9"), 0) -> #NAME?
A20: FALSE | B20: Insulation | F20: FALSE | H20: A.M. (D) | O20: AHAM EXCEEDS | P20: =sum(P19+P21) -> #NAME? | T20: ='Scratch Pad'!G18 | U20: =IF(EQ(T20, ""), "", INDIRECT(T20&"!E3")) | V20: =if(AND(NE(T20, ""), EQ($C$3, U20)), INDIRECT(T20&"!P9"), 0) -> #NAME?
A21: FALSE | B21: Countertops | F21: FALSE | H21: A.M. (D) | O21: AHAM EXCEED CALC. | P21: =if(P5>0,Q5,Q6) -> 130 | T21: ='Scratch Pad'!G19 | U21: =IF(EQ(T21, ""), "", INDIRECT(T21&"!E3")) | V21: =if(AND(NE(T21, ""), EQ($C$3, U21)), INDIRECT(T21&"!P9"), 0) -> #NAME?
A22: FALSE | B22: Backsplash | F22: FALSE | H22: A.M. (D) | T22: ='Scratch Pad'!G20 | U22: =IF(EQ(T22, ""), "", INDIRECT(T22&"!E3")) | V22: =if(AND(NE(T22, ""), EQ($C$3, U22)), INDIRECT(T22&"!P9"), 0) -> #NAME?
A23: FALSE | B23: Cabinetry | F23: FALSE | H23: Extraction | T23: ='Scratch Pad'!G21 | U23: =IF(EQ(T23, ""), "", INDIRECT(T23&"!E3")) | V23: =if(AND(NE(T23, ""), EQ($C$3, U23)), INDIRECT(T23&"!P9"), 0) -> #NAME?
A24: FALSE | B24: Contents | F24: FALSE | H24: Floor (Sqft) | T24: ='Scratch Pad'!G22 | U24: =IF(EQ(T24, ""), "", INDIRECT(T24&"!E3")) | V24: =if(AND(NE(T24, ""), EQ($C$3, U24)), INDIRECT(T24&"!P9"), 0) -> #NAME?
A25: FALSE | B25: Contents (Bag for disposal) | F25: FALSE | H25: Other | O25: Air Mover Calculation | T25: ='Scratch Pad'!G23 | U25: =IF(EQ(T25, ""), "", INDIRECT(T25&"!E3")) | V25: =if(AND(NE(T25, ""), EQ($C$3, U25)), INDIRECT(T25&"!P9"), 0) -> #NAME?
A26: FALSE | B26: Containment | F26: FALSE | H26: Drill Holes (Each)
A27: FALSE | B27: Plastic Coverings | F27: FALSE | H27: Spray Anti-Microbial (Sqft) | O27: Initial air mover | P27: =sum(L13) -> 0 | T27: ='Scratch Pad'!G24 | U27: =IF(EQ(T27, ""), "", INDIRECT(T27&"!E3")) | V27: =if(AND(NE(T27, ""), EQ($C$3, U27)), INDIRECT(T27&"!P9"), 0) -> #NAME?
A28: FALSE | B28: Appliances | F28: FALSE | H28: Drill Holes (Each) | O28: Flooring air movers | P28: =if(Q28>0,S28,Q28) -> 0 | Q28: =if(L14<26,0,1) -> 0 | R28: =sum(L14/50) -> 0 | S28: =roundup(R28,0) -> 0 | T28: ='Scratch Pad'!G25 | U28: =IF(EQ(T28, ""), "", INDIRECT(T28&"!E3")) | V28: =if(AND(NE(T28, ""), EQ($C$3, U28)), INDIRECT(T28&"!P9"), 0) -> #NAME?
A29: FALSE | B29: Plumbing - Various | F29: FALSE | H29: Containment - Zip Pole System (Each) | O29: Ceiling / wall air movers | P29: =roundup(Q29,0) -> 0 | Q29: =sum(L15/100) -> 0 | T29: ='Scratch Pad'!G26 | U29: =IF(EQ(T29, ""), "", INDIRECT(T29&"!E3")) | V29: =if(AND(NE(T29, ""), EQ($C$3, U29)), INDIRECT(T29&"!P9"), 0) -> #NAME?
A30: FALSE | B30: Subcontractor - Various | F30: FALSE | H30: Zippers (Each) | O30: Inset / offset air movers | P30: =sum(L16) -> 0 | T30: ='Scratch Pad'!G27 | U30: =IF(EQ(T30, ""), "", INDIRECT(T30&"!E3")) | V30: =if(AND(NE(T30, ""), EQ($C$3, U30)), INDIRECT(T30&"!P9"), 0) -> #NAME?
A31: FALSE | B31: Mirror | F31: FALSE | H31: Insulation - Vacuum Wall Framing | O31: Total air movers | P31: =sum(P27:P30) -> 0 | T31: ='Scratch Pad'!G28 | U31: =IF(EQ(T31, ""), "", INDIRECT(T31&"!E3")) | V31: =if(AND(NE(T31, ""), EQ($C$3, U31)), INDIRECT(T31&"!P9"), 0) -> #NAME?
A32: FALSE | B32: Other | F32: FALSE | H32: Insulation - Clean Truss System | T32: ='Scratch Pad'!G29 | U32: =IF(EQ(T32, ""), "", INDIRECT(T32&"!E3")) | V32: =if(AND(NE(T32, ""), EQ($C$3, U32)), INDIRECT(T32&"!P9"), 0) -> #NAME?
A33: FALSE | B33: Other | F33: FALSE | H33: Cleaning (Sqft) | L33: =if(P18>0,D4*F4,0) -> 0
A34: FALSE | B34: Other | F34: FALSE | H34: Cleaning Notes
A35: FALSE | B35: Other | F35: FALSE
A36: FALSE | B36: Other | F36: FALSE
A37: Notes | T37: ='Scratch Pad'!G30 | U37: =IF(EQ(T37, ""), "", INDIRECT(T37&"!E3")) | V37: =if(AND(NE(T37, ""), EQ($C$3, U37)), INDIRECT(T37&"!P9"), 0) -> #NAME?
T38: ='Scratch Pad'!G31 | U38: =IF(EQ(T38, ""), "", INDIRECT(T38&"!E3")) | V38: =if(AND(NE(T38, ""), EQ($C$3, U38)), INDIRECT(T38&"!P9"), 0) -> #NAME?
V39: =if(AND(NE(T39, ""), EQ($C$3, U39)), INDIRECT(T39&"!P9"), 0) -> #NAME?
V40: =if(AND(NE(T40, ""), EQ($C$3, U40)), INDIRECT(T40&"!P9"), 0) -> #NAME?
...

Sheet Drying Chambers
L1: Drying Chamber(s) | AM1: Class | AN1: LGR Rating | AO1: Dehu | AP1: AHAM Rating
A2: Delete Chamber | L2: Entrusted | AM2: 1 | AN2: 100 | AO2: Drymax | AP2: 80
AM3: 2 | AN3: 50 | AO3: 7000 | AP3: 130
A4: Delete Tab | AM4: 3 | AN4: 40
AM5: 4 | AN5: 40
V6: 1 | W6: Class | Y6: Input Class | AA6: =IF(Y6=1,"5% or less affected w/minimal absorption", if(Y6=2,"5-40% affected w/minimal absorption", if(Y6=3,"> 40% affected w/minimal absorption",if(Y6=4,"Deep absorption","")))) | AQ6: Chamber Number
V7: 1 | W7: Chamber | Y7: =AQ7 -> 0 | AA7: Room(s) Associated | AM7: Drymax Total | AN7: =sum(Z12:Z14) -> 0 | AO7: =sum(AN7*$AP$2) -> 0 | AQ7: 0
V8: 1 | W8: Room Cubic Volume | Y8: =AQ9 -> 0 | AA8: =AQ11 -> 0 | AM8: 7000 Total | AN8: =sum(Z15:Z17) -> 0 | AO8: =sum(AN8*$AP$3) -> 0 | AQ8: Cubic Volume
V9: 1 | W9: Add. Cubic Volume | AM9: Dehu Total / AHAM Total | AN9: =sum(AN7:AN8) -> 0 | AQ9: 0
V10: 1 | W10: Total Cubic Volume | Y10: =sum(Y8+Y9) -> 0 | AM10: Total AHAM | AN10: =sum(AO7:AO8) -> 0 | AQ10: Associated Room(s)
V11: 1 | W11: Dehumidification | Y11: Install | Z11: Amount | AA11: Days | AB11: Pull | AC11: ACCURACY | AM11: Class | AN11: =if(Y6=1,$AN$2,if(Y6=2,$AN$3,if(Y6=3,$AN$4,if(Y6=4,$AN$5,"")))) | AQ11: 0
V12: 1 | W12: Drymax (Days) | AC12: =if(AN10=0,"",if(AN10<AN12,"AHAM Not Met!",if(AN10>AN15,"AHAM Exceeded!","AHAM Correct!"))) | AM12: Total PPD | AN12: =sum(Y10/AN11) -> #DIV/0!
V13: 1 | W13: Drymax (Days) | AM13: AHAM | AN13: =sum(AN12/AN10) -> #DIV/0!
V14: 1 | W14: Drymax (Days)
V15: 1 | W15: 7000 (Days) | AM15: AHAM EXCEEDS | AN15: =sum(AN12+AN16) -> #DIV/0!
V16: 1 | W16: 7000 (Days) | AM16: AHAM EXCEED CALC. | AN16: =if(AN7>0,$AP$2,$AP$3) -> 130
V17: 1 | W17: 7000 (Days)
V18: 1 | W18: Air Scrubbers | Y18: Install | Z18: Amount | AA18: Days | AB18: Pull | AC18: RECOMMENDED | AM18: Air Changes Per Hr | AN18: 4 | AO18: 60 | AP18: =sum(Y10/AO18)*AN18 -> 0
V19: 1 | W19: Hepa 500 | AC19: =sum(AN20) -> 0 | AM19: HEPA 500 CFM | AN19: 500
V20: 1 | W20: Hepa 500 | AM20: Recommended | AN20: =roundup(AO20,0) -> 0 | AO20: =sum(AP18/AN19) -> 0
V21: 1 | W21: Day(s) | Y21: Day 1 | Z21: Day 2 | AA21: Day 3 | AB21: Day 4 | AC21: Day 5 | AD21: Day 6 | AE21: Day 7 | AF21: Day 8 | AG21: Day 9 | AH21: Day 10
V22: 1 | W22: Temp. Chamber ( °)
V23: 1 | W23: RH Chamber (%)
V24: 1 | W24: Temp. Dehu ( °)
V25: 1 | W25: RH Dehu (%)
V26: 1 | W26: Notes
V27: 1
V28: 1
V29: 1
